# Bug Fix 文件 - CalcTDD 第 5 點

本文件記錄在 Calculator 系統中發現並修復數值溢位（numeric overflow）bug 的完整過程。

---

## 目標

根據 CalcTDD.pdf 第 5 點的要求：
- 在現有系統中找到錯誤
- 用測試捕捉當前行為
- 至少一個測試必須失敗（證明找到了錯誤）
- 修復錯誤
- 確認所有測試通過

---

## 發現的 Bug

### Bug 描述

**問題**：Calculator 類別沒有正確處理數值溢位（numeric overflow）

當運算結果超過 Python float 的上限（約 `±1.7976931348623157e+308`）時，Python 會回傳 `inf`（無限大）或 `-inf`（負無限大），而不是拋出錯誤。

### Bug 識別過程

#### 1. 初步測試

測試極大數字的運算：

```bash
$ python -c "from Calc import Calculator; calc = Calculator(); print(calc.add(1e308, 1e308))"
inf
```

**發現**：運算回傳 `inf` 而不是錯誤。

#### 2. 更多測試

```python
# 加法溢位
calc.add(1e308, 1e308)        # Returns: inf

# 乘法溢位
calc.multiply(1e200, 1e200)   # Returns: inf

# 減法溢位（負無限大）
calc.subtract(-1e308, 1e308)  # Returns: -inf
```

### 為什麼這是個 Bug？

1. **靜默失敗**：回傳 `inf` 而不通知使用者計算失敗
2. **錯誤傳播**：使用 `inf` 繼續計算會產生更多錯誤結果
3. **使用者體驗差**：使用者不知道計算已經失效
4. **違反預期行為**：計算器應該明確報告無法處理的數值

---

## 測試驅動的 Bug 修復流程

### 步驟 1：建立測試捕捉 Bug

建立 `CalcBugFixTest.py` 來測試溢位行為：

```python
import unittest
import math
from Calc import Calculator


class TestCalculatorOverflowBug(unittest.TestCase):
    """Test suite to capture and fix overflow bugs in Calculator."""

    def setUp(self):
        self.calc = Calculator()

    # Tests that demonstrate the BUG (will FAIL initially)

    def test_add_overflow_positive(self):
        """Test that adding very large numbers raises OverflowError"""
        with self.assertRaises(OverflowError):
            result = self.calc.add(1e308, 1e308)

    def test_multiply_overflow(self):
        """Test that multiplying very large numbers raises OverflowError"""
        with self.assertRaises(OverflowError):
            result = self.calc.multiply(1e200, 1e200)

    def test_subtract_overflow_negative(self):
        """Test that subtracting to negative infinity raises OverflowError"""
        with self.assertRaises(OverflowError):
            result = self.calc.subtract(-1e308, 1e308)

    # Tests that should PASS (normal operations)

    def test_add_normal_numbers(self):
        """Test that normal addition still works"""
        result = self.calc.add(100, 200)
        self.assertEqual(result, 300)

    def test_add_large_but_safe_numbers(self):
        """Test that large but safe numbers work"""
        result = self.calc.add(1e100, 1e100)
        self.assertEqual(result, 2e100)
        self.assertFalse(math.isinf(result))

    def test_multiply_normal_numbers(self):
        """Test that normal multiplication still works"""
        result = self.calc.multiply(10, 20)
        self.assertEqual(result, 200)

    def test_divide_normal_numbers(self):
        """Test that normal division still works"""
        result = self.calc.divide(100, 2)
        self.assertEqual(result, 50.0)
```

**測試設計**：
- 3 個測試檢查溢位行為（預期會失敗）
- 4 個測試確保正常運算仍然正常（預期會通過）

---

### 步驟 2：執行測試證明 Bug 存在

**執行測試**：

```bash
$ uv run python CalcBugFixTest.py -v
```

**結果**：

```
test_add_large_but_safe_numbers ... ok
test_add_normal_numbers ... ok
test_add_overflow_positive ... FAIL
test_divide_normal_numbers ... ok
test_multiply_normal_numbers ... ok
test_multiply_overflow ... FAIL
test_subtract_overflow_negative ... FAIL

======================================================================
FAIL: test_add_overflow_positive
----------------------------------------------------------------------
Traceback (most recent call last):
  File "CalcBugFixTest.py", line 32, in test_add_overflow_positive
    result = self.calc.add(1e308, 1e308)
AssertionError: OverflowError not raised

======================================================================
FAIL: test_multiply_overflow
----------------------------------------------------------------------
Traceback (most recent call last):
  File "CalcBugFixTest.py", line 38, in test_multiply_overflow
    result = self.calc.multiply(1e200, 1e200)
AssertionError: OverflowError not raised

======================================================================
FAIL: test_subtract_overflow_negative
----------------------------------------------------------------------
Traceback (most recent call last):
  File "CalcBugFixTest.py", line 43, in test_subtract_overflow_negative
    result = self.calc.subtract(-1e308, 1e308)
AssertionError: OverflowError not raised

----------------------------------------------------------------------
Ran 7 tests in 0.000s

FAILED (failures=3)
```

✅ **成功證明 Bug**：3 個測試失敗，證明 Calculator 沒有正確處理溢位。

---

### 步驟 3：修復 Bug

**修復策略**：在每個運算方法中加入溢位檢查，使用 `math.isinf()` 檢測無限大。

**修復前的 Calc.py**：

```python
class Calculator:
    def add(self, a, b):
        return a + b

    def subtract(self, a, b):
        return a - b

    def multiply(self, a, b):
        return a * b

    def divide(self, a, b):
        if b == 0:
            raise ValueError("Cannot divide by zero")
        return a / b
```

**修復後的 Calc.py**：

```python
import math


class Calculator:
    def add(self, a, b):
        result = a + b
        if math.isinf(result):
            raise OverflowError(f"Addition overflow: {a} + {b} exceeds float limits")
        return result

    def subtract(self, a, b):
        result = a - b
        if math.isinf(result):
            raise OverflowError(f"Subtraction overflow: {a} - {b} exceeds float limits")
        return result

    def multiply(self, a, b):
        result = a * b
        if math.isinf(result):
            raise OverflowError(f"Multiplication overflow: {a} * {b} exceeds float limits")
        return result

    def divide(self, a, b):
        if b == 0:
            raise ValueError("Cannot divide by zero")
        result = a / b
        if math.isinf(result):
            raise OverflowError(f"Division overflow: {a} / {b} exceeds float limits")
        return result
```

**修復內容**：
1. ✅ 導入 `math` 模組
2. ✅ 在每個方法中先計算結果
3. ✅ 使用 `math.isinf()` 檢查結果是否為無限大
4. ✅ 如果是無限大，拋出 `OverflowError` 並附帶描述性訊息
5. ✅ 保持原有的除以零檢查

---

### 步驟 4：驗證修復成功

**執行 Bug 修復測試**：

```bash
$ uv run python CalcBugFixTest.py -v
```

**結果**：

```
test_add_large_but_safe_numbers ... ok
test_add_normal_numbers ... ok
test_add_overflow_positive ... ok
test_divide_normal_numbers ... ok
test_multiply_normal_numbers ... ok
test_multiply_overflow ... ok
test_subtract_overflow_negative ... ok

----------------------------------------------------------------------
Ran 7 tests in 0.000s

OK
```

✅ **所有測試通過**：包括原本失敗的 3 個溢位測試。

---

### 步驟 5：驗證沒有破壞現有功能

**執行原有的 CalcTest**：

```bash
$ uv run python CalcTest.py -v
```

**結果**：

```
test_add (__main__.TestCalculator) ... ok
test_divide (__main__.TestCalculator) ... ok
test_divide_by_zero (__main__.TestCalculator) ... ok
test_divide_with_remainder (__main__.TestCalculator) ... ok
test_multiply (__main__.TestCalculator) ... ok
test_subtract (__main__.TestCalculator) ... ok

----------------------------------------------------------------------
Ran 6 tests in 0.000s

OK
```

✅ **無回歸問題**：原有的 6 個測試全部通過。

**執行 MainTest**：

```bash
$ uv run python MainTest.py -v
```

**結果**：

```
test_main_demonstrates_addition ... ok
test_main_demonstrates_division ... ok
test_main_demonstrates_division_with_remainder ... ok
test_main_demonstrates_multiplication ... ok
test_main_demonstrates_subtraction ... ok
test_main_prints_calculator_title ... ok
test_main_prints_completion_message ... ok
test_main_prints_hello ... ok
test_main_uses_calculator_class ... ok

----------------------------------------------------------------------
Ran 9 tests in 0.000s

OK
```

✅ **整合測試通過**：MainTest 的 9 個測試全部通過。

---

## 測試總結

### 修復前的測試狀態

| 測試套件 | 測試數量 | 通過 | 失敗 |
|---------|---------|------|------|
| CalcTest.py | 6 | 6 | 0 |
| MainTest.py | 9 | 9 | 0 |
| CalcBugFixTest.py | 7 | 4 | **3** ❌ |
| **總計** | **22** | **19** | **3** |

### 修復後的測試狀態

| 測試套件 | 測試數量 | 通過 | 失敗 |
|---------|---------|------|------|
| CalcTest.py | 6 | 6 | 0 |
| MainTest.py | 9 | 9 | 0 |
| CalcBugFixTest.py | 7 | 7 | 0 ✅ |
| **總計** | **22** | **22** ✅ | **0** |

**測試通過率**：從 86.4% (19/22) 提升到 **100% (22/22)**

---

## Bug 修復的好處

### 1. 改進的錯誤處理
- **修復前**：回傳 `inf`，靜默失敗
- **修復後**：拋出 `OverflowError`，明確告知使用者

### 2. 更好的使用者體驗

```python
# 修復前
result = calc.add(1e308, 1e308)  # Returns: inf (no error)
print(result)  # Output: inf

# 修復後
try:
    result = calc.add(1e308, 1e308)
except OverflowError as e:
    print(f"Error: {e}")
# Output: Error: Addition overflow: 1e+308 + 1e+308 exceeds float limits
```

### 3. 防止錯誤傳播

```python
# 修復前：錯誤會傳播
result1 = calc.add(1e308, 1e308)     # inf
result2 = calc.multiply(result1, 2)   # inf
result3 = calc.subtract(result2, 100) # inf

# 修復後：立即捕獲錯誤
try:
    result1 = calc.add(1e308, 1e308)
except OverflowError:
    # 處理錯誤，不會繼續傳播
    pass
```

### 4. 符合 Python 最佳實踐

Python 標準庫中的數學函式在溢位時通常會拋出異常，我們的修復使 Calculator 的行為與 Python 標準保持一致。

---

## 實際測試範例

### 測試溢位檢測

```python
from Calc import Calculator

calc = Calculator()

# Test 1: Addition overflow
try:
    result = calc.add(1e308, 1e308)
except OverflowError as e:
    print(f"✓ Caught overflow: {e}")

# Test 2: Multiplication overflow
try:
    result = calc.multiply(1e200, 1e200)
except OverflowError as e:
    print(f"✓ Caught overflow: {e}")

# Test 3: Normal operations still work
result = calc.add(1e100, 1e100)
print(f"✓ Normal operation: 1e100 + 1e100 = {result}")
```

**輸出**：

```
✓ Caught overflow: Addition overflow: 1e+308 + 1e+308 exceeds float limits
✓ Caught overflow: Multiplication overflow: 1e+200 * 1e+200 exceeds float limits
✓ Normal operation: 1e100 + 1e100 = 2e+100
```

---

## Git 提交

### Commit 訊息

```
Fix: Add overflow detection to Calculator (Task 5)

This commit fixes a bug where Calculator would silently return
'inf' for numeric overflow instead of raising an error.

Bug Description:
- Operations exceeding float limits returned 'inf' or '-inf'
- No error notification to users
- Errors would propagate through subsequent calculations

Fix Implementation:
- Import math module
- Check results with math.isinf() after each operation
- Raise OverflowError with descriptive message if overflow detected
- Maintain all existing functionality

Tests:
- Added CalcBugFixTest.py with 7 tests
- 3 tests initially failed (demonstrating the bug)
- All 3 now pass after fix
- All existing tests (CalcTest + MainTest) still pass
- Total: 22/22 tests passing (100%)

This demonstrates Task 5: finding and repairing a fault in an
existing system using TDD methodology.
```

---

## 學習成果

通過這次 Bug 修復，展示了：

### ✅ Bug 發現能力
識別出真實存在的數值溢位問題。

### ✅ 測試先行
在修復前先建立測試，證明 Bug 的存在。

### ✅ TDD 方法論
1. 寫失敗的測試（紅燈）
2. 修復 Bug（綠燈）
3. 驗證沒有破壞現有功能

### ✅ 完整的測試覆蓋
- 測試 Bug 場景（溢位）
- 測試正常場景（不破壞現有功能）
- 測試邊界情況（大數但不溢位）

### ✅ 良好的錯誤處理
使用適當的異常類型（`OverflowError`）和描述性訊息。

---

## 繳交檢查清單

根據 CalcTDD.pdf 第 5 點的要求，確認以下項目：

- ✅ **找到錯誤**：數值溢位 bug
- ✅ **建立測試捕捉當前行為**：CalcBugFixTest.py（7 個測試）
- ✅ **至少一個測試失敗**：3 個測試失敗，證明找到 bug
- ✅ **修復錯誤**：在所有方法中加入溢位檢查
- ✅ **所有測試通過**：22/22 測試全部通過

### 需要提交的內容

1. **有錯誤的程式碼版本**：
   - 可從 git 歷史查看修復前的 Calc.py

2. **測試程式碼**：
   - CalcBugFixTest.py（新增）
   - CalcTest.py（確保未破壞）
   - MainTest.py（確保未破壞）

3. **測試失敗的截圖**：
   - CalcBugFixTest 執行結果（3 個失敗）

4. **修復後的程式碼**：
   - 新的 Calc.py（加入溢位檢查）

5. **測試通過的截圖**：
   - CalcBugFixTest 執行結果（全部通過）
   - CalcTest 執行結果（全部通過）
   - MainTest 執行結果（全部通過）

6. **說明文件**：
   - BUG_FIX_DOCUMENTATION.md（本文件）

---

## 結論

本次 Bug 修復成功展示了：

1. ✅ 在真實系統中識別問題的能力
2. ✅ 使用測試驅動方法修復 Bug
3. ✅ 確保修復不會破壞現有功能
4. ✅ 改進系統的健壯性和使用者體驗

這個過程體現了 TDD 在維護和改進現有系統中的價值：測試不僅幫助我們發現問題，還確保我們的修復是正確且安全的。

---

**修復完成日期**：2025年
**Bug 嚴重程度**：中等（影響極大數值的計算）
**修復效果**：完全解決，無副作用
